<?xml version="1.0" ?>
<!-- =================================================================================== -->
<!-- |    This document was autogenerated by xacro from werdna_v2.xacro                | -->
<!-- |    EDITING THIS FILE BY HAND IS NOT RECOMMENDED                                 | -->
<!-- =================================================================================== -->
<robot name="werdna">
  <material name="white">
    <color rgba="1 1 1 1"/>
  </material>
  <material name="orange">
    <color rgba="1 0.3 0.1 1"/>
  </material>
  <material name="blue">
    <color rgba="0.2 0.2 1 1"/>
  </material>
  <material name="black">
    <color rgba="0 0 0 1"/>
  </material>
  <material name="red">
    <color rgba="1 0 0 1"/>
  </material>
  <!-- Specify some standard inertial calculations https://en.wikipedia.org/wiki/List_of_moments_of_inertia -->
  <!-- These make use of xacro's mathematical functionality -->
  <!-- *********** base link *********** -->
  <!-- <link name="base_link"/> -->
  <!-- CHASSIS -->
  <link name="base_link">
    <inertial>
      <origin rpy="0 0 0" xyz="0 0 0"/>
      <mass value="3.0"/>
      <inertia ixx="0.009225" ixy="0.0" ixz="0.0" iyy="0.013600000000000001" iyz="0.0" izz="0.015625"/>
    </inertial>
    <visual>
      <origin rpy="0.0 0.0 0.0" xyz="0.0 0.0 0.0"/>
      <geometry>
        <box size="0.2 0.15 0.12"/>
      </geometry>
      <material name="blue"/>
    </visual>
    <collision>
      <origin rpy="0.0 0.0 0.0" xyz="0.0 0.0 0.0"/>
      <geometry>
        <box size="0.2 0.15 0.12"/>
      </geometry>
      <material name="blue"/>
    </collision>
  </link>
  <!-- chassis_joint -->
  <!-- <joint name="chassis_joint" type="fixed">
    <origin rpy="0.0 0.0 0.0" xyz="0.0 0.0 0.06"/>
    <parent link="base_link"/>
    <child link="chassis_link"/>
  </joint> -->
  <!-- imu -->
  <link name="imu_link">
    <inertial>
      <origin rpy="0 0 0" xyz="0 0 0"/>
      <mass value="0.01"/>
      <inertia ixx="1.6666666666666668e-07" ixy="0.0" ixz="0.0" iyy="1.6666666666666668e-07" iyz="0.0" izz="1.6666666666666668e-07"/>
    </inertial>
    <visual>
      <origin rpy="0.0 0.0 0.0" xyz="0.0 0.0 0.0"/>
      <geometry>
        <box size="0.01 0.01 0.01"/>
      </geometry>
      <material name="white"/>
    </visual>
    <collision>
      <origin rpy="0.0 0.0 0.0" xyz="0.0 0.0 0.0"/>
      <geometry>
        <box size="0.01 0.01 0.01"/>
      </geometry>
      <material name="white"/>
    </collision>
  </link>
  <!-- imu joint -->
  <joint name="imu_joint" type="fixed">
    <origin rpy="0.0 0.0 0.0" xyz="0.0 0.0 0.065"/>
    <parent link="base_link"/>
    <child link="imu_link"/>
  </joint>
  <!-- LEFT HIP MOTOR -->
  <link name="left_hip_motor_link">
    <visual>
      <origin rpy="0 0 0" xyz="0 0 0"/>
      <geometry>
        <cylinder length="0.0285" radius="0.046"/>
      </geometry>
      <material name="red"/>
    </visual>
    <collision>
      <origin rpy="0 0 0" xyz="0 0 0"/>
      <geometry>
        <cylinder length="0.0285" radius="0.046"/>
      </geometry>
      <material name="red"/>
    </collision>
    <inertial>
      <origin rpy="0 0 0" xyz="0 0 0"/>
      <mass value="0.336"/>
      <inertia ixx="0.000200487" ixy="0.0" ixz="0.0" iyy="0.000200487" iyz="0.0" izz="0.000355488"/>
    </inertial>
  </link>
  <joint name="left_hip_motor_joint" type="revolute">
    <origin rpy="1.5707963267948966 -0.6897975409348593 0.0" xyz="0.0 0.08925 0.0"/>
    <parent link="base_link"/>
    <child link="left_hip_motor_link"/>
    <axis xyz="0.0 0.0 1.0"/>
    <limit effort="10.0" lower="-3.142" upper="3.142" velocity="10.0"/>
  </joint>
  <!-- LEFT HIP ROD -->
  <link name="left_hip_link">
    <visual>
      <origin rpy="0 1.5707963267948966 0" xyz="-0.1 0 0"/>
      <geometry>
        <box size="0.01 0.01 0.2"/>
      </geometry>
      <material name="red"/>
    </visual>
    <collision>
      <origin rpy="0 1.5707963267948966 0" xyz="-0.1 0 0"/>
      <geometry>
        <box size="0.01 0.01 0.2"/>
      </geometry>
      <material name="red"/>
    </collision>
    <inertial>
      <origin rpy="0 1.5707963267948966 0" xyz="-0.1 0 0"/>
      <mass value="0.2"/>
      <inertia ixx="0.0006683333333333335" ixy="0.0" ixz="0.0" iyy="0.0006683333333333335" iyz="0.0" izz="3.3333333333333333e-06"/>
    </inertial>
  </link>
  <joint name="left_hip_joint" type="fixed">
    <origin rpy="0.0 0.0 0.0" xyz="0.0 0.0 -0.01925"/>
    <parent link="left_hip_motor_link"/>
    <child link="left_hip_link"/>
  </joint>
  <!-- LEFT KNEE MOTOR -->
  <link name="left_knee_motor_link">
    <visual>
      <origin rpy="0 0 0" xyz="0 0 0"/>
      <geometry>
        <cylinder length="0.0285" radius="0.046"/>
      </geometry>
      <material name="red"/>
    </visual>
    <collision>
      <origin rpy="0 0 0" xyz="0 0 0"/>
      <geometry>
        <cylinder length="0.0285" radius="0.046"/>
      </geometry>
      <material name="red"/>
    </collision>
    <inertial>
      <origin rpy="0 0 0" xyz="0 0 0"/>
      <mass value="0.336"/>
      <inertia ixx="0.000200487" ixy="0.0" ixz="0.0" iyy="0.000200487" iyz="0.0" izz="0.000355488"/>
    </inertial>
  </link>
  <joint name="left_knee_motor_joint" type="revolute">
    <origin rpy="0.0 0 -1.1336790410021163" xyz="-0.2 0 -0.01925"/>
    <parent link="left_hip_link"/>
    <child link="left_knee_motor_link"/>
    <axis xyz="0.0 0.0 -1.0"/>
    <limit effort="10.0" lower="-3.142" upper="3.142" velocity="10.0"/>
  </joint>
  <!-- LEFT KNEE ROD -->
  <link name="left_knee_link">
    <visual>
      <origin rpy="0 0 0" xyz="0 0 0.1"/>
      <geometry>
        <box size="0.01 0.01 0.2"/>
      </geometry>
      <material name="red"/>
    </visual>
    <collision>
      <origin rpy="0 0 0" xyz="0 0 0.1"/>
      <geometry>
        <box size="0.01 0.01 0.2"/>
      </geometry>
      <material name="red"/>
    </collision>
    <inertial>
      <origin rpy="0 0 0" xyz="0 0 0.1"/>
      <mass value="0.2"/>
      <inertia ixx="0.0006683333333333335" ixy="0.0" ixz="0.0" iyy="0.0006683333333333335" iyz="0.0" izz="3.3333333333333333e-06"/>
    </inertial>
  </link>
  <joint name="left_knee_joint" type="fixed">
    <origin rpy="0.0 1.5707963267948966 0.0" xyz="0 0 -0.01925"/>
    <parent link="left_knee_motor_link"/>
    <child link="left_knee_link"/>
  </joint>
  <!-- LEFT WHEEL -->
  <link name="left_wheel">
    <visual>
      <origin rpy="0 0 0" xyz="0 0 0"/>
      <geometry>
        <cylinder length="0.045" radius="0.0855"/>
      </geometry>
      <material name="black"/>
    </visual>
    <collision>
      <origin rpy="0 0 0" xyz="0 0 0"/>
      <geometry>
        <cylinder length="0.045" radius="0.0855"/>
      </geometry>
    </collision>
    <inertial>
      <origin rpy="0 0 0" xyz="0 0 0"/>
      <mass value="2.2"/>
      <inertia ixx="0.0043918875" ixy="0.0" ixz="0.0" iyy="0.0043918875" iyz="0.0" izz="0.008041275000000002"/>
    </inertial>
  </link>
  <joint name="left_wheel_joint" type="continuous">
    <origin rpy="0 1.5707963267948966 0" xyz="0.0275 0 0.2"/>
    <parent link="left_knee_link"/>
    <child link="left_wheel"/>
    <axis xyz="0.0 0.0 1.0"/>
  </joint>
  <!-- RIGHT HIP MOTOR -->
  <link name="right_hip_motor_link">
    <visual>
      <origin rpy="0 0 0" xyz="0 0 0"/>
      <geometry>
        <cylinder length="0.0285" radius="0.046"/>
      </geometry>
      <material name="red"/>
    </visual>
    <collision>
      <origin rpy="0 0 0" xyz="0 0 0"/>
      <geometry>
        <cylinder length="0.0285" radius="0.046"/>
      </geometry>
      <material name="red"/>
    </collision>
    <inertial>
      <origin rpy="0 0 0" xyz="0 0 0"/>
      <mass value="0.336"/>
      <inertia ixx="0.000200487" ixy="0.0" ixz="0.0" iyy="0.000200487" iyz="0.0" izz="0.000355488"/>
    </inertial>
  </link>
  <joint name="right_hip_motor_joint" type="revolute">
    <origin rpy="1.5707963267948966 -0.6897975409348593 0.0" xyz="0.0 -0.08925 0.0"/>
    <parent link="base_link"/>
    <child link="right_hip_motor_link"/>
    <axis xyz="0.0 0.0 1.0"/>
    <limit effort="10.0" lower="-3.142" upper="3.142" velocity="10.0"/>
  </joint>
  <!-- RIGHT HIP LINK -->
  <link name="right_hip_link">
    <visual>
      <origin rpy="0 1.5707963267948966 0" xyz="-0.1 0 0"/>
      <geometry>
        <box size="0.01 0.01 0.2"/>
      </geometry>
      <material name="red"/>
    </visual>
    <collision>
      <origin rpy="0 1.5707963267948966 0" xyz="-0.1 0 0"/>
      <geometry>
        <box size="0.01 0.01 0.2"/>
      </geometry>
      <material name="red"/>
    </collision>
    <inertial>
      <origin rpy="0 1.5707963267948966 0" xyz="-0.1 0 0"/>
      <mass value="0.2"/>
      <inertia ixx="0.0006683333333333335" ixy="0.0" ixz="0.0" iyy="0.0006683333333333335" iyz="0.0" izz="3.3333333333333333e-06"/>
    </inertial>
  </link>
  <joint name="right_hip_joint" type="fixed">
    <origin rpy="0.0 0.0 0.0" xyz="0.0 0.0 0.01925"/>
    <parent link="right_hip_motor_link"/>
    <child link="right_hip_link"/>
  </joint>
  <!-- RIGHT KNEE MOTOR -->
  <link name="right_knee_motor_link">
    <visual>
      <origin rpy="0 0 0" xyz="0 0 0"/>
      <geometry>
        <cylinder length="0.0285" radius="0.046"/>
      </geometry>
      <material name="red"/>
    </visual>
    <collision>
      <origin rpy="0 0 0" xyz="0 0 0"/>
      <geometry>
        <cylinder length="0.0285" radius="0.046"/>
      </geometry>
      <material name="red"/>
    </collision>
    <inertial>
      <origin rpy="0 0 0" xyz="0 0 0"/>
      <mass value="0.336"/>
      <inertia ixx="0.000200487" ixy="0.0" ixz="0.0" iyy="0.000200487" iyz="0.0" izz="0.000355488"/>
    </inertial>
  </link>
  <joint name="right_knee_motor_joint" type="revolute">
    <origin rpy="0.0 0 -1.1336790410021163" xyz="-0.2 0 0.01925"/>
    <parent link="right_hip_link"/>
    <child link="right_knee_motor_link"/>
    <axis xyz="0.0 0.0 -1.0"/>
    <limit effort="10.0" lower="-3.142" upper="3.142" velocity="10.0"/>
  </joint>
  <!-- RIGHT KNEE ROD -->
  <link name="right_knee_link">
    <visual>
      <origin rpy="0 0 0" xyz="0 0 0.1"/>
      <geometry>
        <box size="0.01 0.01 0.2"/>
      </geometry>
      <material name="red"/>
    </visual>
    <collision>
      <origin rpy="0 0 0" xyz="0 0 0.1"/>
      <geometry>
        <box size="0.01 0.01 0.2"/>
      </geometry>
      <material name="red"/>
    </collision>
    <inertial>
      <origin rpy="0 0 0" xyz="0 0 0.1"/>
      <mass value="0.2"/>
      <inertia ixx="0.0006683333333333335" ixy="0.0" ixz="0.0" iyy="0.0006683333333333335" iyz="0.0" izz="3.3333333333333333e-06"/>
    </inertial>
  </link>
  <joint name="right_knee_joint" type="fixed">
    <origin rpy="0.0 1.5707963267948966 0.0" xyz="0 0 0.01925"/>
    <parent link="right_knee_motor_link"/>
    <child link="right_knee_link"/>
  </joint>
  <!-- RIGHT WHEEL -->
  <link name="right_wheel">
    <visual>
      <origin rpy="0 0 0" xyz="0 0 0"/>
      <geometry>
        <cylinder length="0.045" radius="0.0855"/>
      </geometry>
      <material name="black"/>
    </visual>
    <collision>
      <origin rpy="0 0 0" xyz="0 0 0"/>
      <geometry>
        <cylinder length="0.045" radius="0.0855"/>
      </geometry>
    </collision>
    <inertial>
      <origin rpy="0 0 0" xyz="0 0 0"/>
      <mass value="2.2"/>
      <inertia ixx="0.0043918875" ixy="0.0" ixz="0.0" iyy="0.0043918875" iyz="0.0" izz="0.008041275000000002"/>
    </inertial>
  </link>
  <joint name="right_wheel_joint" type="continuous">
    <origin rpy="0 1.5707963267948966 0" xyz="-0.0275 0 0.2"/>
    <parent link="right_knee_link"/>
    <child link="right_wheel"/>
    <axis xyz="0.0 0.0 1.0"/>
  </joint>
</robot>
