<?xml version="1.0" ?>
<!-- =================================================================================== -->
<!-- |    This document was autogenerated by xacro from werdna.xacro                   | -->
<!-- |    EDITING THIS FILE BY HAND IS NOT RECOMMENDED                                 | -->
<!-- =================================================================================== -->
<robot name="werdna">
  <material name="white">
    <color rgba="1 1 1 1"/>
  </material>
  <material name="orange">
    <color rgba="1 0.3 0.1 1"/>
  </material>
  <material name="blue">
    <color rgba="0.2 0.2 1 1"/>
  </material>
  <material name="black">
    <color rgba="0 0 0 1"/>
  </material>
  <material name="red">
    <color rgba="1 0 0 1"/>
  </material>
  <!-- Specify some standard inertial calculations https://en.wikipedia.org/wiki/List_of_moments_of_inertia -->
  <!-- These make use of xacro's mathematical functionality -->
  <!-- *********** base link *********** -->
  <link name="base_link">
    <inertial>
      <origin rpy="0 0 0" xyz="0 0 0"/>
      <mass value="4.0"/>
      <inertia ixx="0.0123" ixy="0.0" ixz="0.0" iyy="0.018133333333333335" iyz="0.0" izz="0.020833333333333332"/>
    </inertial>
    <visual>
      <origin rpy="0.0 0.0 0.0" xyz="0.0 0.0 0.0"/>
      <geometry>
        <box size="0.2 0.15 0.12"/>
      </geometry>
      <material name="blue"/>
    </visual>
    <collision>
      <origin rpy="0.0 0.0 0.0" xyz="0.0 0.0 0.0"/>
      <geometry>
        <box size="0.2 0.15 0.12"/>
      </geometry>
      <material name="blue"/>
    </collision>
  </link>
  <!-- imu -->
  <link name="imu_link">
    <inertial>
      <origin rpy="0 0 0" xyz="0 0 0"/>
      <mass value="0.01"/>
      <inertia ixx="1.6666666666666668e-07" ixy="0.0" ixz="0.0" iyy="1.6666666666666668e-07" iyz="0.0" izz="1.6666666666666668e-07"/>
    </inertial>
    <visual>
      <origin rpy="0.0 0.0 0.0" xyz="0.0 0.0 0.0"/>
      <geometry>
        <box size="0.01 0.01 0.01"/>
      </geometry>
      <material name="white"/>
    </visual>
    <collision>
      <origin rpy="0.0 0.0 0.0" xyz="0.0 0.0 0.0"/>
      <geometry>
        <box size="0.01 0.01 0.01"/>
      </geometry>
      <material name="white"/>
    </collision>
  </link>
  <!-- hips -->
  <link name="left_hip_link">
    <visual>
      <origin rpy="0 0 0" xyz="0 0 -0.1"/>
      <geometry>
        <box size="0.05 0.05 0.2"/>
      </geometry>
      <material name="red"/>
    </visual>
    <collision>
      <origin rpy="0 0 0" xyz="0 0 -0.1"/>
      <geometry>
        <box size="0.025 0.025 0.17500000000000002"/>
      </geometry>
      <material name="red"/>
    </collision>
    <inertial>
      <origin rpy="0 0 0" xyz="0 0 -0.1"/>
      <mass value="1.0"/>
      <inertia ixx="0.0035416666666666674" ixy="0.0" ixz="0.0" iyy="0.0035416666666666674" iyz="0.0" izz="0.00041666666666666675"/>
    </inertial>
  </link>
  <link name="right_hip_link">
    <visual>
      <origin rpy="0 0 0" xyz="0 0 -0.1"/>
      <geometry>
        <box size="0.05 0.05 0.2"/>
      </geometry>
      <material name="red"/>
    </visual>
    <collision>
      <origin rpy="0 0 0" xyz="0 0 -0.1"/>
      <geometry>
        <box size="0.025 0.025 0.17500000000000002"/>
      </geometry>
      <material name="red"/>
    </collision>
    <inertial>
      <origin rpy="0 0 0" xyz="0 0 -0.1"/>
      <mass value="1.0"/>
      <inertia ixx="0.0035416666666666674" ixy="0.0" ixz="0.0" iyy="0.0035416666666666674" iyz="0.0" izz="0.00041666666666666675"/>
    </inertial>
  </link>
  <!-- knees -->
  <link name="left_knee_link">
    <visual>
      <origin rpy="0 0 0" xyz="0 0 0.1"/>
      <geometry>
        <box size="0.05 0.05 0.2"/>
      </geometry>
      <material name="orange"/>
    </visual>
    <collision>
      <origin rpy="0 0 0" xyz="0 0 0.1"/>
      <geometry>
        <box size="0.025 0.025 0.17500000000000002"/>
      </geometry>
      <material name="orange"/>
    </collision>
    <inertial>
      <origin rpy="0 0 0" xyz="0 0 0.1"/>
      <mass value="1.0"/>
      <inertia ixx="0.0035416666666666674" ixy="0.0" ixz="0.0" iyy="0.0035416666666666674" iyz="0.0" izz="0.00041666666666666675"/>
    </inertial>
  </link>
  <link name="right_knee_link">
    <visual>
      <origin rpy="0 0 0" xyz="0 0 0.1"/>
      <geometry>
        <box size="0.05 0.05 0.2"/>
      </geometry>
      <material name="orange"/>
    </visual>
    <collision>
      <origin rpy="0 0 0" xyz="0 0 0.1"/>
      <geometry>
        <box size="0.025 0.025 0.17500000000000002"/>
      </geometry>
      <material name="orange"/>
    </collision>
    <inertial>
      <origin rpy="0 0 0" xyz="0 0 0.1"/>
      <mass value="1.0"/>
      <inertia ixx="0.0035416666666666674" ixy="0.0" ixz="0.0" iyy="0.0035416666666666674" iyz="0.0" izz="0.00041666666666666675"/>
    </inertial>
  </link>
  <!-- wheels -->
  <link name="left_wheel">
    <visual>
      <origin rpy="0 0 0" xyz="0 0 0"/>
      <geometry>
        <cylinder length="0.045" radius="0.0855"/>
      </geometry>
      <material name="black"/>
    </visual>
    <collision>
      <origin rpy="0 0 0" xyz="0 0 0"/>
      <geometry>
        <cylinder length="0.045" radius="0.0855"/>
      </geometry>
    </collision>
    <inertial>
      <origin rpy="0 0 0" xyz="0 0 0"/>
      <mass value="2.2"/>
      <inertia ixx="0.0043918875" ixy="0.0" ixz="0.0" iyy="0.0043918875" iyz="0.0" izz="0.008041275000000002"/>
    </inertial>
  </link>
  <link name="right_wheel">
    <visual>
      <origin rpy="0 0 0" xyz="0 0 0"/>
      <geometry>
        <cylinder length="0.045" radius="0.0855"/>
      </geometry>
      <material name="black"/>
    </visual>
    <collision>
      <origin rpy="0 0 0" xyz="0 0 0"/>
      <geometry>
        <cylinder length="0.045" radius="0.0855"/>
      </geometry>
    </collision>
    <inertial>
      <origin rpy="0 0 0" xyz="0 0 0"/>
      <mass value="2.2"/>
      <inertia ixx="0.0043918875" ixy="0.0" ixz="0.0" iyy="0.0043918875" iyz="0.0" izz="0.008041275000000002"/>
    </inertial>
  </link>
  <!-- imu joint -->
  <joint name="imu_joint" type="fixed">
    <origin rpy="0.0 0.0 0.0" xyz="0.0 0.0 0.065"/>
    <parent link="base_link"/>
    <child link="imu_link"/>
  </joint>
  <!-- hip joints -->
  <joint name="left_hip_joint" type="revolute">
    <origin rpy="0.0 1.571 0.0" xyz="0.0 0.1 0.0"/>
    <parent link="base_link"/>
    <child link="left_hip_link"/>
    <axis xyz="0.0 1.0 0.0"/>
    <limit effort="10.0" lower="-3.142" upper="3.142" velocity="100.0"/>
    <dynamics friction="2000"/>
  </joint>
  <joint name="right_hip_joint" type="revolute">
    <origin rpy="0.0 1.571 0.0" xyz="0.0 -0.1 0.0"/>
    <parent link="base_link"/>
    <child link="right_hip_link"/>
    <axis xyz="0.0 1.0 0.0"/>
    <limit effort="10.0" lower="-3.142" upper="3.142" velocity="100.0"/>
    <dynamics friction="2000"/>
  </joint>
  <!-- knee joints  -->
  <joint name="left_knee_joint" type="revolute">
    <origin rpy="0.0 0.0 0.0" xyz="0.0 0.05 -0.2"/>
    <parent link="left_hip_link"/>
    <child link="left_knee_link"/>
    <axis xyz="0.0 1.0 0.0"/>
    <limit effort="10.0" lower="-3.142" upper="3.142" velocity="100.0"/>
    <dynamics friction="2000"/>
  </joint>
  <joint name="right_knee_joint" type="revolute">
    <origin rpy="0.0 0.0 0.0" xyz="0.0 -0.05 -0.2"/>
    <parent link="right_hip_link"/>
    <child link="right_knee_link"/>
    <axis xyz="0.0 1.0 0.0"/>
    <limit effort="10.0" lower="-3.142" upper="3.142" velocity="100.0"/>
    <dynamics friction="2000"/>
  </joint>
  <!-- wheel joints -->
  <joint name="left_wheel_joint" type="continuous">
    <origin rpy="1.571 0 0" xyz="0 0.0475 0.2"/>
    <parent link="left_knee_link"/>
    <child link="left_wheel"/>
    <axis xyz="0.0 0.0 -1.0"/>
  </joint>
  <joint name="right_wheel_joint" type="continuous">
    <origin rpy="1.571 0 0" xyz="0 -0.0475 0.2"/>
    <parent link="right_knee_link"/>
    <child link="right_wheel"/>
    <axis xyz="0.0 0 -1.0"/>
  </joint>
</robot>
